{"trial_id": "04", "hyperparameters": {"space": [{"class_name": "Int", "config": {"name": "batch_size", "default": null, "conditions": [], "min_value": 8, "max_value": 128, "step": 8, "sampling": "linear"}}, {"class_name": "Int", "config": {"name": "num_bilstm_layers", "default": null, "conditions": [], "min_value": 1, "max_value": 2, "step": 1, "sampling": "linear"}}, {"class_name": "Int", "config": {"name": "units", "default": null, "conditions": [], "min_value": 8, "max_value": 512, "step": 8, "sampling": "linear"}}, {"class_name": "Choice", "config": {"name": "activation", "default": "tanh", "conditions": [], "values": ["relu", "sigmoid", "tanh"], "ordered": false}}, {"class_name": "Float", "config": {"name": "dropout_rate", "default": 0.0, "conditions": [], "min_value": 0.0, "max_value": 0.5, "step": 0.1, "sampling": "linear"}}, {"class_name": "Choice", "config": {"name": "optimizer", "default": "Adam", "conditions": [], "values": ["Adam", "SGD", "RMSprop"], "ordered": false}}, {"class_name": "Float", "config": {"name": "adam_lr", "default": 1e-05, "conditions": [], "min_value": 1e-05, "max_value": 0.01, "step": null, "sampling": "log"}}, {"class_name": "Float", "config": {"name": "sgd_lr", "default": 1e-05, "conditions": [], "min_value": 1e-05, "max_value": 0.01, "step": null, "sampling": "log"}}], "values": {"batch_size": 88, "num_bilstm_layers": 2, "units": 488, "activation": "tanh", "dropout_rate": 0.1, "optimizer": "SGD", "adam_lr": 0.005947688565213911, "sgd_lr": 2.7142518559786354e-05}}, "metrics": {"metrics": {}}, "score": null, "best_step": 0, "status": "FAILED", "message": "Traceback (most recent call last):\n  File \"/home/enge/.local/lib/python3.12/site-packages/keras_tuner/src/engine/base_tuner.py\", line 274, in _try_run_and_update_trial\n    self._run_and_update_trial(trial, *fit_args, **fit_kwargs)\n  File \"/home/enge/.local/lib/python3.12/site-packages/keras_tuner/src/engine/base_tuner.py\", line 239, in _run_and_update_trial\n    results = self.run_trial(trial, *fit_args, **fit_kwargs)\n              ^^^^^^^^^^^^^^^^^^^^^^^^^^^^^^^^^^^^^^^^^^^^^^\n  File \"/home/enge/.local/lib/python3.12/site-packages/keras_tuner/src/engine/tuner.py\", line 314, in run_trial\n    obj_value = self._build_and_fit_model(trial, *args, **copied_kwargs)\n                ^^^^^^^^^^^^^^^^^^^^^^^^^^^^^^^^^^^^^^^^^^^^^^^^^^^^^^^^\n  File \"/home/enge/.local/lib/python3.12/site-packages/keras_tuner/src/engine/tuner.py\", line 233, in _build_and_fit_model\n    results = self.hypermodel.fit(hp, model, *args, **kwargs)\n              ^^^^^^^^^^^^^^^^^^^^^^^^^^^^^^^^^^^^^^^^^^^^^^^\n  File \"/home/enge/.local/lib/python3.12/site-packages/keras_tuner/src/engine/hypermodel.py\", line 149, in fit\n    return model.fit(*args, **kwargs)\n           ^^^^^^^^^^^^^^^^^^^^^^^^^^\n  File \"/home/enge/.local/lib/python3.12/site-packages/keras/src/utils/traceback_utils.py\", line 122, in error_handler\n    raise e.with_traceback(filtered_tb) from None\n  File \"/home/enge/.local/lib/python3.12/site-packages/tensorflow/python/eager/execute.py\", line 59, in quick_execute\n    except TypeError as e:\ntensorflow.python.framework.errors_impl.InvalidArgumentError: Graph execution error:\n\nDetected at node sub defined at (most recent call last):\n  File \"<frozen runpy>\", line 198, in _run_module_as_main\n\n  File \"<frozen runpy>\", line 88, in _run_code\n\n  File \"/home/enge/.local/lib/python3.12/site-packages/ipykernel_launcher.py\", line 18, in <module>\n\n  File \"/home/enge/.local/lib/python3.12/site-packages/traitlets/config/application.py\", line 1075, in launch_instance\n\n  File \"/home/enge/.local/lib/python3.12/site-packages/ipykernel/kernelapp.py\", line 739, in start\n\n  File \"/home/enge/.local/lib/python3.12/site-packages/tornado/platform/asyncio.py\", line 205, in start\n\n  File \"/usr/lib/python3.12/asyncio/base_events.py\", line 641, in run_forever\n\n  File \"/usr/lib/python3.12/asyncio/base_events.py\", line 1987, in _run_once\n\n  File \"/usr/lib/python3.12/asyncio/events.py\", line 88, in _run\n\n  File \"/home/enge/.local/lib/python3.12/site-packages/ipykernel/kernelbase.py\", line 545, in dispatch_queue\n\n  File \"/home/enge/.local/lib/python3.12/site-packages/ipykernel/kernelbase.py\", line 534, in process_one\n\n  File \"/home/enge/.local/lib/python3.12/site-packages/ipykernel/kernelbase.py\", line 437, in dispatch_shell\n\n  File \"/home/enge/.local/lib/python3.12/site-packages/ipykernel/ipkernel.py\", line 362, in execute_request\n\n  File \"/home/enge/.local/lib/python3.12/site-packages/ipykernel/kernelbase.py\", line 778, in execute_request\n\n  File \"/home/enge/.local/lib/python3.12/site-packages/ipykernel/ipkernel.py\", line 449, in do_execute\n\n  File \"/home/enge/.local/lib/python3.12/site-packages/ipykernel/zmqshell.py\", line 549, in run_cell\n\n  File \"/home/enge/.local/lib/python3.12/site-packages/IPython/core/interactiveshell.py\", line 3075, in run_cell\n\n  File \"/home/enge/.local/lib/python3.12/site-packages/IPython/core/interactiveshell.py\", line 3130, in _run_cell\n\n  File \"/home/enge/.local/lib/python3.12/site-packages/IPython/core/async_helpers.py\", line 128, in _pseudo_sync_runner\n\n  File \"/home/enge/.local/lib/python3.12/site-packages/IPython/core/interactiveshell.py\", line 3334, in run_cell_async\n\n  File \"/home/enge/.local/lib/python3.12/site-packages/IPython/core/interactiveshell.py\", line 3517, in run_ast_nodes\n\n  File \"/home/enge/.local/lib/python3.12/site-packages/IPython/core/interactiveshell.py\", line 3577, in run_code\n\n  File \"/tmp/ipykernel_208771/3962036212.py\", line 61, in <module>\n\n  File \"/home/enge/.local/lib/python3.12/site-packages/keras_tuner/src/engine/base_tuner.py\", line 234, in search\n\n  File \"/home/enge/.local/lib/python3.12/site-packages/keras_tuner/src/engine/base_tuner.py\", line 274, in _try_run_and_update_trial\n\n  File \"/home/enge/.local/lib/python3.12/site-packages/keras_tuner/src/engine/base_tuner.py\", line 239, in _run_and_update_trial\n\n  File \"/home/enge/.local/lib/python3.12/site-packages/keras_tuner/src/engine/tuner.py\", line 314, in run_trial\n\n  File \"/home/enge/.local/lib/python3.12/site-packages/keras_tuner/src/engine/tuner.py\", line 233, in _build_and_fit_model\n\n  File \"/home/enge/.local/lib/python3.12/site-packages/keras_tuner/src/engine/hypermodel.py\", line 149, in fit\n\n  File \"/home/enge/.local/lib/python3.12/site-packages/keras/src/utils/traceback_utils.py\", line 117, in error_handler\n\n  File \"/home/enge/.local/lib/python3.12/site-packages/keras/src/backend/tensorflow/trainer.py\", line 320, in fit\n\n  File \"/home/enge/.local/lib/python3.12/site-packages/keras/src/backend/tensorflow/trainer.py\", line 121, in one_step_on_iterator\n\n  File \"/home/enge/.local/lib/python3.12/site-packages/keras/src/backend/tensorflow/trainer.py\", line 108, in one_step_on_data\n\n  File \"/home/enge/.local/lib/python3.12/site-packages/keras/src/backend/tensorflow/trainer.py\", line 77, in train_step\n\n  File \"/home/enge/.local/lib/python3.12/site-packages/keras/src/trainers/trainer.py\", line 491, in compute_metrics\n\n  File \"/home/enge/.local/lib/python3.12/site-packages/keras/src/trainers/compile_utils.py\", line 330, in update_state\n\n  File \"/home/enge/.local/lib/python3.12/site-packages/keras/src/trainers/compile_utils.py\", line 17, in update_state\n\n  File \"/home/enge/.local/lib/python3.12/site-packages/keras/src/metrics/reduction_metrics.py\", line 204, in update_state\n\n  File \"/tmp/ipykernel_208771/3143388025.py\", line 29, in r2\n\nIncompatible shapes: [32,12,1] vs. [32,1]\n\t [[{{node sub}}]] [Op:__inference_one_step_on_iterator_465186]\n"}